# Copyright (C) 2001-2020, Python Software Foundation
# This file is distributed under the same license as the Python package.
# Maintained by the python-doc-es workteam.
# docs-es@python.org /
# https://mail.python.org/mailman3/lists/docs-es.python.org/
# Check https://github.com/python/python-docs-es/blob/3.8/TRANSLATORS to
# get the list of volunteers
#
#, fuzzy
msgid ""
msgstr ""
"Project-Id-Version: Python 3.8\n"
"Report-Msgid-Bugs-To: \n"
"POT-Creation-Date: 2020-05-05 12:54+0200\n"
"PO-Revision-Date: YEAR-MO-DA HO:MI+ZONE\n"
"Last-Translator: FULL NAME <EMAIL@ADDRESS>\n"
"Language-Team: python-doc-es\n"
"MIME-Version: 1.0\n"
"Content-Type: text/plain; charset=utf-8\n"
"Content-Transfer-Encoding: 8bit\n"
"Generated-By: Babel 2.8.0\n"

#: ../Doc/library/asyncio-exceptions.rst:8
msgid "Exceptions"
msgstr ""

#: ../Doc/library/asyncio-exceptions.rst:10
msgid "**Source code:** :source:`Lib/asyncio/exceptions.py`"
msgstr ""

#: ../Doc/library/asyncio-exceptions.rst:16
msgid "The operation has exceeded the given deadline."
msgstr ""

#: ../Doc/library/asyncio-exceptions.rst:19
msgid ""
"This exception is different from the builtin :exc:`TimeoutError` exception."
msgstr ""

#: ../Doc/library/asyncio-exceptions.rst:25
msgid "The operation has been cancelled."
msgstr ""

#: ../Doc/library/asyncio-exceptions.rst:27
msgid ""
"This exception can be caught to perform custom operations when asyncio Tasks "
"are cancelled.  In almost all situations the exception must be re-raised."
msgstr ""

#: ../Doc/library/asyncio-exceptions.rst:33
msgid ":exc:`CancelledError` is now a subclass of :class:`BaseException`."
msgstr ""

#: ../Doc/library/asyncio-exceptions.rst:38
msgid "Invalid internal state of :class:`Task` or :class:`Future`."
msgstr ""

#: ../Doc/library/asyncio-exceptions.rst:40
msgid ""
"Can be raised in situations like setting a result value for a *Future* "
"object that already has a result value set."
msgstr ""

#: ../Doc/library/asyncio-exceptions.rst:46
msgid ""
"The \"sendfile\" syscall is not available for the given socket or file type."
msgstr ""

#: ../Doc/library/asyncio-exceptions.rst:49
msgid "A subclass of :exc:`RuntimeError`."
msgstr ""

#: ../Doc/library/asyncio-exceptions.rst:54
msgid "The requested read operation did not complete fully."
msgstr ""

#: ../Doc/library/asyncio-exceptions.rst:56
msgid "Raised by the :ref:`asyncio stream APIs<asyncio-streams>`."
msgstr ""

#: ../Doc/library/asyncio-exceptions.rst:58
msgid "This exception is a subclass of :exc:`EOFError`."
msgstr ""

#: ../Doc/library/asyncio-exceptions.rst:62
msgid "The total number (:class:`int`) of expected bytes."
msgstr ""

#: ../Doc/library/asyncio-exceptions.rst:66
msgid "A string of :class:`bytes` read before the end of stream was reached."
msgstr ""

#: ../Doc/library/asyncio-exceptions.rst:71
msgid "Reached the buffer size limit while looking for a separator."
msgstr ""

#: ../Doc/library/asyncio-exceptions.rst:73
msgid "Raised by the :ref:`asyncio stream APIs <asyncio-streams>`."
msgstr ""

#: ../Doc/library/asyncio-exceptions.rst:77
msgid "The total number of to be consumed bytes."
msgstr ""
